2022-05-10 12:46:13,084 - INFO - Created bot in community timer and scrubbing strategy watch
2022-05-10 12:46:13,086 - INFO - SETUP PHASE
2022-05-10 12:46:13,086 - INFO - We are in TEST mode
2022-05-10 12:46:13,086 - INFO - Attempting login with username "sean.carter.99.test" and password "99problems".
2022-05-10 12:46:22,778 - INFO - Login succeeded at attempt #1
2022-05-10 12:47:03,327 - ERROR - Error! Saving html to ./failures/timer_watch_test-0.html
Traceback (most recent call last):
  File "/Users/avliu/Documents/Research/youtube_audits/burst/scrub_main.py", line 128, in main
    scrub_experiment(bot)
  File "/Users/avliu/Documents/Research/youtube_audits/burst/scrub_main.py", line 27, in scrub_experiment
    time.sleep(5)
  File "/Users/avliu/Documents/Research/youtube_audits/burst/scrub_main.py", line 27, in scrub_experiment
    time.sleep(5)
  File "_pydevd_bundle/pydevd_cython_darwin_310_64.pyx", line 1590, in _pydevd_bundle.pydevd_cython_darwin_310_64.ThreadTracer.__call__
  File "_pydevd_bundle/pydevd_cython_darwin_310_64.pyx", line 930, in _pydevd_bundle.pydevd_cython_darwin_310_64.PyDBFrame.trace_dispatch
  File "_pydevd_bundle/pydevd_cython_darwin_310_64.pyx", line 921, in _pydevd_bundle.pydevd_cython_darwin_310_64.PyDBFrame.trace_dispatch
  File "_pydevd_bundle/pydevd_cython_darwin_310_64.pyx", line 318, in _pydevd_bundle.pydevd_cython_darwin_310_64.PyDBFrame.do_wait_suspend
  File "/Applications/PyCharm.app/Contents/plugins/python/helpers/pydev/pydevd.py", line 1147, in do_wait_suspend
    self._do_wait_suspend(thread, frame, event, arg, suspend_type, from_this_thread)
  File "/Applications/PyCharm.app/Contents/plugins/python/helpers/pydev/pydevd.py", line 1162, in _do_wait_suspend
    time.sleep(0.01)
KeyboardInterrupt
2022-05-10 12:47:03,333 - WARNING - Retrying (Retry(total=2, connect=None, read=None, redirect=None, status=None)) after connection broken by 'NewConnectionError('<urllib3.connection.HTTPConnection object at 0x7fa3605f0ca0>: Failed to establish a new connection: [Errno 61] Connection refused')': /session/19ff74ccfbe8ffb5a3e3e29e873b5d67/source
2022-05-10 12:47:03,334 - WARNING - Retrying (Retry(total=1, connect=None, read=None, redirect=None, status=None)) after connection broken by 'NewConnectionError('<urllib3.connection.HTTPConnection object at 0x7fa3605f1570>: Failed to establish a new connection: [Errno 61] Connection refused')': /session/19ff74ccfbe8ffb5a3e3e29e873b5d67/source
2022-05-10 12:47:03,334 - WARNING - Retrying (Retry(total=0, connect=None, read=None, redirect=None, status=None)) after connection broken by 'NewConnectionError('<urllib3.connection.HTTPConnection object at 0x7fa3605f1180>: Failed to establish a new connection: [Errno 61] Connection refused')': /session/19ff74ccfbe8ffb5a3e3e29e873b5d67/source
